Traceback (most recent call last):
  File "/usr/local/lib/python3.10/dist-packages/jupyter_cache/executors/utils.py", line 58, in single_nb_execution
    executenb(
  File "/usr/local/lib/python3.10/dist-packages/nbclient/client.py", line 1305, in execute
    return NotebookClient(nb=nb, resources=resources, km=km, **kwargs).execute()
  File "/usr/local/lib/python3.10/dist-packages/jupyter_core/utils/__init__.py", line 166, in wrapped
    return loop.run_until_complete(inner)
  File "/usr/lib/python3.10/asyncio/base_events.py", line 649, in run_until_complete
    return future.result()
  File "/usr/local/lib/python3.10/dist-packages/nbclient/client.py", line 705, in async_execute
    await self.async_execute_cell(
  File "/usr/local/lib/python3.10/dist-packages/nbclient/client.py", line 1058, in async_execute_cell
    await self._check_raise_for_error(cell, cell_index, exec_reply)
  File "/usr/local/lib/python3.10/dist-packages/nbclient/client.py", line 914, in _check_raise_for_error
    raise CellExecutionError.from_cell_and_msg(cell, exec_reply_content)
nbclient.exceptions.CellExecutionError: An error occurred while executing the following cell:
------------------
# Membuat objek imputer dengan strategi imputasi rata-rata
imputer = SimpleImputer(strategy='mean')

# Mengisi nilai yang hilang pada data input
X_train_filled = imputer.fit_transform(X_train_scaled)

# Melatih model dengan data yang telah diisi dengan nilai yang hilang
mlp_clf.fit(X_train_filled, y_train)

------------------


[0;31m[0m
[0;31mNameError[0mTraceback (most recent call last)
[0;32m<ipython-input-10-7d8bdd01225f>[0m in [0;36m<cell line: 8>[0;34m()[0m
[1;32m      6[0m [0;34m[0m[0m
[1;32m      7[0m [0;31m# Melatih model dengan data yang telah diisi dengan nilai yang hilang[0m[0;34m[0m[0;34m[0m[0m
[0;32m----> 8[0;31m [0mmlp_clf[0m[0;34m.[0m[0mfit[0m[0;34m([0m[0mX_train_filled[0m[0;34m,[0m [0my_train[0m[0;34m)[0m[0;34m[0m[0;34m[0m[0m
[0m
[0;31mNameError[0m: name 'mlp_clf' is not defined

